<?xml version="1.0" ?>
<robot name="carmodel" xmlns:xacro="https://www.ros.org/wiki/xacro" >

<link name="body_link">
<visual>
<geometry>
<box size="0.184 0.08 0.044"/>
</geometry>
<origin rpy="0 0 0" xyz="0 0 0.036"/>
<material name="yellow">
<color rgba="1 1 0 0.7"/>
</material>
</visual>
<collision>
<geometry>
<box size="0.184 0.08 0.044"/>
</geometry>
<origin rpy="0 0 0" xyz="0 0 0.036"/>
</collision>
<inertial>
    <mass value="0.15"/>
    <inertia ixx="0.000446" ixy="0.0" ixz="0.0" iyy="0.000104" iyz="0.0" izz="0.000501"/>
</inertial>
</link>

<joint name="car_wheel1_joint" type="continuous">
<parent link="body_link"/>
<child link="car_wheel1_link"/>
<axis xyz="0 1 0"/>
<origin xyz="0.048 0.046 0.014"/>
</joint>

<link name="car_wheel1_link">
<visual>
<geometry>
<cylinder length="0.012" radius="0.014"/>
</geometry>
<origin rpy="1.57075 1.57075 0" xyz="0 0 0"/>
<material name="red">
<color rgba="1 0 1 1"/>
</material>
</visual>
<collision>
      <geometry>
          <cylinder length="0.012" radius="0.014"/>
      </geometry>
    <origin rpy="1.57075 1.57075 0" xyz="0 0 0"/>
</collision>
<inertial>
      <mass value="0.02"/>
      <inertia ixx="0.0000012" ixy="0.0" ixz="0.0" iyy="0.0000012" iyz="0.0" izz="0.0000059"/>
</inertial>
</link>

<joint name="car_wheel2_joint" type="continuous">
<parent link="body_link"/>
<child link="car_wheel2_link"/>
<axis xyz="0 1 0"/>
<origin xyz="0.048 -0.046 0.014"/>
</joint>

<link name="car_wheel2_link">
<visual>
<geometry>
<cylinder length="0.012" radius="0.014"/>
</geometry>
<origin rpy="1.57075 1.57075 0" xyz="0 0 0"/>
<material name="red">
<color rgba="1 0 1 1"/>
</material>
</visual>
<collision>
      <geometry>
          <cylinder length="0.012" radius="0.014"/>
      </geometry>
    <origin rpy="1.57075 1.57075 0" xyz="0 0 0"/>
</collision>
<inertial>
      <mass value="0.02"/>
      <inertia ixx="0.0000012" ixy="0.0" ixz="0.0" iyy="0.0000012" iyz="0.0" izz="0.0000059"/>
</inertial>
</link>

<joint name="car_wheel3_joint" type="continuous">
<parent link="body_link"/>
<child link="car_wheel3_link"/>
<axis xyz="0 1 0"/>
<origin xyz="-0.06 -0.046 0.014"/>
</joint>

<link name="car_wheel3_link">
<visual>
<geometry>
<cylinder length="0.012" radius="0.014"/>
</geometry>
<origin rpy="1.57075 1.57075 0" xyz="0 0 0"/>
<material name="red">
<color rgba="1 0 1 1"/>
</material>
</visual>
<collision>
      <geometry>
          <cylinder length="0.012" radius="0.014"/>
      </geometry>
    <origin rpy="1.57075 1.57075 0" xyz="0 0 0"/>
</collision>
<inertial>
      <mass value="0.02"/>
      <inertia ixx="0.0000012" ixy="0.0" ixz="0.0" iyy="0.0000012" iyz="0.0" izz="0.0000059"/>
</inertial>
</link>

<joint name="car_wheel4_joint" type="continuous">
<parent link="body_link"/>
<child link="car_wheel4_link"/>
<axis xyz="0 1 0"/>
<origin xyz="-0.06 0.046 0.014"/>
</joint>

<link name="car_wheel4_link">
<visual>
<geometry>
<cylinder length="0.012" radius="0.014"/>
</geometry>
<origin rpy="1.57075 1.57075 0" xyz="0 0 0"/>
<material name="red">
<color rgba="1 0 1 1"/>
</material>
</visual>
<collision>
      <geometry>
          <cylinder length="0.012" radius="0.014"/>
      </geometry>
    <origin rpy="1.57075 1.57075 0" xyz="0 0 0"/>
</collision>
<inertial>
      <mass value="0.02"/>
      <inertia ixx="0.0000012" ixy="0.0" ixz="0.0" iyy="0.0000012" iyz="0.0" izz="0.0000059"/>
</inertial>
</link>
</robot>